Workbook

Sheet Climb
A1: Time step | B1: 60 | C1: s
A2: Wing area | B2: 845 | C2: m^2
A3: Aspect ratio | B3: 7.53
A4: e | B4: 0.84
A5: Empty weight | B5: 276800 | C5: kg
A6: Payload | B6: 42800 | C6: Kg
A7: Fuel | B7: 50000 | C7: l | D7: Fuel | E7: =B7*0.804 -> 40200 | F7: kg
A8: Thrust | B8: 0 | C8: 0.9 | D8: Velocity (M)
B9: 338000 | C9: 180000 | D9: Thrust (N)
A10: Lambda | B10: =(B9-C9)/C8 -> 175555.56
A11: Thrust laps rate | B11: 0.96
A12: TSFC | B12: 0.00016 | C12: N/N/S
A13: Num Engines | B13: 4
A15: Altitude | B15: Mass | C15: Temperature | D15: Preassure | E15: Air density | F15: Speed of sound | G15: IAS | H15: Mtrue | I15: TAS (m/s) | J15: TAS (Knot) | K15: Lift coef. | L15: Cdrag_0 | M15: Drag coef. | N15: Drag | O15: Thrust | P15: Total Thrust | Q15: dh/dt | R15: Climbing angle | S15: dW/dt | T15: Distance | U15: New mass | V15: Cumulative distance | W15: Cumulative altitude | X15: Flight time | Y15: Remaining Fuel
A16: 0 | B16: =B5+B6+E7 -> 359800 | C16: =IF(A16<=11000,A16*Constants!$B$2+Constants!$B$1,216.7) -> 288.2 | D16: =IF(A16<=11000, Constants!$B$4*(1-0.0065*Climb!A16/Constants!$B$1)^5.2561, 22632*EXP(9.81*(11000-A16)/Constants!$B$6/C16)) -> 101325 | E16: =D16/(Constants!$B$6*Climb!C16) -> 1.2250131 | F16: =SQRT(Constants!$B$8*Constants!$B$6*Climb!C16) -> 340.29217 | G16: =VLOOKUP(TRUNC(A16/1000),Flight!$A$3:$C$17,3,FALSE) -> 210 | H16: =SQRT(5*((Constants!$B$3/Climb!E16*((1+0.2*(Climb!G16/661.5)^2)^3.5-1)+1)^0.286-1)) -> 0.31761894 | I16: =H16*F16 -> 108.08324 | J16: =I16/Constants!$B$9 -> 210.09719 | K16: =2*B16*Constants!$B$7/(Climb!E16*Climb!$B$2*Climb!I16^2) -> 0.58377571 | L16: 0.02 | M16: =K16^2/(PI()*$B$3*$B$4)+L16 -> 0.03715015 | N16: =0.5*E16*Climb!I16^2*Climb!$B$2*Climb!M16 -> 224618.08 | O16: =($B$9-$B$10*H16)*(E16/Constants!$B$3)^$B$11 -> 282243.13 | P16: =O16*$B$13 -> 1128972.5 | Q16: =(P16-N16)*I16/B16/Constants!$B$7 -> 27.692799 | R16: =ASIN(Q16/I16) -> 0.25910687 | S16: =P16*$B$1*$B$12/Constants!$B$7 -> 1104.8049 | T16: =I16*COS(R16)*$B$1 -> 6268.5199 | U16: =B16-S16 -> 358695.2 | V16: =T16 -> 6268.5199 | W16: =A16+Q16*$B$1 -> 1661.568 | X16: =$B$1 -> 60 | Y16: =$E$7-B16+U16 -> 39095.195
A17: =W16 -> 1661.568 | B17: =U16 -> 358695.2 | C17: =IF(A17<=11000,A17*Constants!$B$2+Constants!$B$1,216.7) -> 277.39981 | D17: =IF(A17<=11000, Constants!$B$4*(1-0.0065*Climb!A17/Constants!$B$1)^5.2561, 22632*EXP(9.81*(11000-A17)/Constants!$B$6/C17)) -> 82895.198 | E17: =D17/(Constants!$B$6*Climb!C17) -> 1.0412172 | F17: =SQRT(Constants!$B$8*Constants!$B$6*Climb!C17) -> 333.85512 | G17: =VLOOKUP(TRUNC(A17/1000),Flight!$A$3:$C$17,3,FALSE) -> 210 | H17: =SQRT(5*((Constants!$B$3/Climb!E17*((1+0.2*(Climb!G17/661.5)^2)^3.5-1)+1)^0.286-1)) -> 0.34377438 | I17: =H17*F17 -> 114.77084 | J17: =I17/Constants!$B$9 -> 223.09685 | K17: =2*B17*Constants!$B$7/(Climb!E17*Climb!$B$2*Climb!I17^2) -> 0.60724428 | L17: 0.02 | M17: =K17^2/(PI()*$B$3*$B$4)+L17 -> 0.038556785 | N17: =0.5*E17*Climb!I17^2*Climb!$B$2*Climb!M17 -> 223425.09 | O17: =($B$9-$B$10*H17)*(E17/Constants!$B$3)^$B$11 -> 237533.22 | P17: =O17*$B$13 -> 950132.87 | Q17: =(P17-N17)*I17/B17/Constants!$B$7 -> 23.702644 | R17: =ASIN(Q17/I17) -> 0.20801846 | S17: =P17*$B$1*$B$12/Constants!$B$7 -> 929.79363 | T17: =I17*COS(R17)*$B$1 -> 6737.7969 | U17: =B17-S17 -> 357765.4 | V17: =V16+T17 -> 13006.317 | W17: =A17+Q17*$B$1 -> 3083.7266 | X17: =X16+$B$1 -> 120 | Y17: =Y16-B17+U17 -> 38165.401
A18: =W17 -> 3083.7266 | B18: =U17 -> 357765.4 | C18: =IF(A18<=11000,A18*Constants!$B$2+Constants!$B$1,216.7) -> 268.15578 | D18: =IF(A18<=11000, Constants!$B$4*(1-0.0065*Climb!A18/Constants!$B$1)^5.2561, 22632*EXP(9.81*(11000-A18)/Constants!$B$6/C18)) -> 69368.906 | E18: =D18/(Constants!$B$6*Climb!C18) -> 0.90135483 | F18: =SQRT(Constants!$B$8*Constants!$B$6*Climb!C18) -> 328.24532 | G18: =VLOOKUP(TRUNC(A18/1000),Flight!$A$3:$C$17,3,FALSE) -> 230 | H18: =SQRT(5*((Constants!$B$3/Climb!E18*((1+0.2*(Climb!G18/661.5)^2)^3.5-1)+1)^0.286-1)) -> 0.40345057 | I18: =H18*F18 -> 132.43076 | J18: =I18/Constants!$B$9 -> 257.42503 | K18: =2*B18*Constants!$B$7/(Climb!E18*Climb!$B$2*Climb!I18^2) -> 0.52549319 | L18: 0.02 | M18: =K18^2/(PI()*$B$3*$B$4)+L18 -> 0.033896648 | N18: =0.5*E18*Climb!I18^2*Climb!$B$2*Climb!M18 -> 226389.88 | O18: =($B$9-$B$10*H18)*(E18/Constants!$B$3)^$B$11 -> 199012.46 | P18: =O18*$B$13 -> 796049.85 | Q18: =(P18-N18)*I18/B18/Constants!$B$7 -> 21.494989 | R18: =ASIN(Q18/I18) -> 0.16303241 | S18: =P18*$B$1*$B$12/Constants!$B$7 -> 779.00902 | T18: =I18*COS(R18)*$B$1 -> 7840.4808 | U18: =B18-S18 -> 356986.39 | V18: =V17+T18 -> 20846.798 | W18: =A18+Q18*$B$1 -> 4373.4259 | X18: =X17+$B$1 -> 180 | Y18: =Y17-B18+U18 -> 37386.392
A19: =W18 -> 4373.4259 | B19: =U18 -> 356986.39 | C19: =IF(A19<=11000,A19*Constants!$B$2+Constants!$B$1,216.7) -> 259.77273 | D19: =IF(A19<=11000, Constants!$B$4*(1-0.0065*Climb!A19/Constants!$B$1)^5.2561, 22632*EXP(9.81*(11000-A19)/Constants!$B$6/C19)) -> 58703.544 | E19: =D19/(Constants!$B$6*Climb!C19) -> 0.78738812 | F19: =SQRT(Constants!$B$8*Constants!$B$6*Climb!C19) -> 323.0738 | G19: =VLOOKUP(TRUNC(A19/1000),Flight!$A$3:$C$17,3,FALSE) -> 250 | H19: =SQRT(5*((Constants!$B$3/Climb!E19*((1+0.2*(Climb!G19/661.5)^2)^3.5-1)+1)^0.286-1)) -> 0.46725769 | I19: =H19*F19 -> 150.95872 | J19: =I19/Constants!$B$9 -> 293.44053 | K19: =2*B19*Constants!$B$7/(Climb!E19*Climb!$B$2*Climb!I19^2) -> 0.46194331 | L19: 0.02 | M19: =K19^2/(PI()*$B$3*$B$4)+L19 -> 0.030738738 | N19: =0.5*E19*Climb!I19^2*Climb!$B$2*Climb!M19 -> 233033.32 | O19: =($B$9-$B$10*H19)*(E19/Constants!$B$3)^$B$11 -> 167463.54 | P19: =O19*$B$13 -> 669854.16 | Q19: =(P19-N19)*I19/B19/Constants!$B$7 -> 18.829591 | R19: =ASIN(Q19/I19) -> 0.1250591 | S19: =P19*$B$1*$B$12/Constants!$B$7 -> 655.51477 | T19: =I19*COS(R19)*$B$1 -> 8986.7867 | U19: =B19-S19 -> 356330.88 | V19: =V18+T19 -> 29833.584 | W19: =A19+Q19*$B$1 -> 5503.2014 | X19: =X18+$B$1 -> 240 | Y19: =Y18-B19+U19 -> 36730.878
A20: =W19 -> 5503.2014 | B20: =U19 -> 356330.88 | C20: =IF(A20<=11000,A20*Constants!$B$2+Constants!$B$1,216.7) -> 252.42919 | D20: =IF(A20<=11000, Constants!$B$4*(1-0.0065*Climb!A20/Constants!$B$1)^5.2561, 22632*EXP(9.81*(11000-A20)/Constants!$B$6/C20)) -> 50489.948 | E20: =D20/(Constants!$B$6*Climb!C20) -> 0.69692084 | F20: =SQRT(Constants!$B$8*Constants!$B$6*Climb!C20) -> 318.47457 | G20: =VLOOKUP(TRUNC(A20/1000),Flight!$A$3:$C$17,3,FALSE) -> 260 | H20: =SQRT(5*((Constants!$B$3/Climb!E20*((1+0.2*(Climb!G20/661.5)^2)^3.5-1)+1)^0.286-1)) -> 0.51433525 | I20: =H20*F20 -> 163.80269 | J20: =I20/Constants!$B$9 -> 318.40724 | K20: =2*B20*Constants!$B$7/(Climb!E20*Climb!$B$2*Climb!I20^2) -> 0.44245613 | L20: 0.02 | M20: =K20^2/(PI()*$B$3*$B$4)+L20 -> 0.029851816 | N20: =0.5*E20*Climb!I20^2*Climb!$B$2*Climb!M20 -> 235843.01 | O20: =($B$9-$B$10*H20)*(E20/Constants!$B$3)^$B$11 -> 144138.92 | P20: =O20*$B$13 -> 576555.7 | Q20: =(P20-N20)*I20/B20/Constants!$B$7 -> 15.96566 | R20: =ASIN(Q20/I20) -> 0.097623842 | S20: =P20*$B$1*$B$12/Constants!$B$7 -> 564.21353 | T20: =I20*COS(R20)*$B$1 -> 9781.3656 | U20: =B20-S20 -> 355766.66 | V20: =V19+T20 -> 39614.95 | W20: =A20+Q20*$B$1 -> 6461.141 | X20: =X19+$B$1 -> 300 | Y20: =Y19-B20+U20 -> 36166.664
A21: =W20 -> 6461.141 | B21: =U20 -> 355766.66 | C21: =IF(A21<=11000,A21*Constants!$B$2+Constants!$B$1,216.7) -> 246.20258 | D21: =IF(A21<=11000, Constants!$B$4*(1-0.0065*Climb!A21/Constants!$B$1)^5.2561, 22632*EXP(9.81*(11000-A21)/Constants!$B$6/C21)) -> 44278.425 | E21: =D21/(Constants!$B$6*Climb!C21) -> 0.62663935 | F21: =SQRT(Constants!$B$8*Constants!$B$6*Climb!C21) -> 314.52217 | G21: =VLOOKUP(TRUNC(A21/1000),Flight!$A$3:$C$17,3,FALSE) -> 290 | H21: =SQRT(5*((Constants!$B$3/Climb!E21*((1+0.2*(Climb!G21/661.5)^2)^3.5-1)+1)^0.286-1)) -> 0.60068574 | I21: =H21*F21 -> 188.92899 | J21: =I21/Constants!$B$9 -> 367.24889 | K21: =2*B21*Constants!$B$7/(Climb!E21*Climb!$B$2*Climb!I21^2) -> 0.36931139 | L21: 0.02 | M21: =K21^2/(PI()*$B$3*$B$4)+L21 -> 0.026863747 | N21: =0.5*E21*Climb!I21^2*Climb!$B$2*Climb!M21 -> 253868.11 | O21: =($B$9-$B$10*H21)*(E21/Constants!$B$3)^$B$11 -> 122190.01 | P21: =O21*$B$13 -> 488760.05 | Q21: =(P21-N21)*I21/B21/Constants!$B$7 -> 12.715471 | R21: =ASIN(Q21/I21) -> 0.067353827 | S21: =P21*$B$1*$B$12/Constants!$B$7 -> 478.2973 | T21: =I21*COS(R21)*$B$1 -> 11310.036 | U21: =B21-S21 -> 355288.37 | V21: =V20+T21 -> 50924.986 | W21: =A21+Q21*$B$1 -> 7224.0693 | X21: =X20+$B$1 -> 360 | Y21: =Y20-B21+U21 -> 35688.367
A22: =W21 -> 7224.0693 | B22: =U21 -> 355288.37 | C22: =IF(A22<=11000,A22*Constants!$B$2+Constants!$B$1,216.7) -> 241.24355 | D22: =IF(A22<=11000, Constants!$B$4*(1-0.0065*Climb!A22/Constants!$B$1)^5.2561, 22632*EXP(9.81*(11000-A22)/Constants!$B$6/C22)) -> 39787.308 | E22: =D22/(Constants!$B$6*Climb!C22) -> 0.57465469 | F22: =SQRT(Constants!$B$8*Constants!$B$6*Climb!C22) -> 311.33849 | G22: =VLOOKUP(TRUNC(A22/1000),Flight!$A$3:$C$17,3,FALSE) -> 290 | H22: =SQRT(5*((Constants!$B$3/Climb!E22*((1+0.2*(Climb!G22/661.5)^2)^3.5-1)+1)^0.286-1)) -> 0.6249849 | I22: =H22*F22 -> 194.58186 | J22: =I22/Constants!$B$9 -> 378.2372 | K22: =2*B22*Constants!$B$7/(Climb!E22*Climb!$B$2*Climb!I22^2) -> 0.3791505 | L22: 0.02 | M22: =K22^2/(PI()*$B$3*$B$4)+L22 -> 0.027234344 | N22: =0.5*E22*Climb!I22^2*Climb!$B$2*Climb!M22 -> 250354.43 | O22: =($B$9-$B$10*H22)*(E22/Constants!$B$3)^$B$11 -> 110379.57 | P22: =O22*$B$13 -> 441518.29 | Q22: =(P22-N22)*I22/B22/Constants!$B$7 -> 10.672303 | R22: =ASIN(Q22/I22) -> 0.054874906 | S22: =P22*$B$1*$B$12/Constants!$B$7 -> 432.06683 | T22: =I22*COS(R22)*$B$1 -> 11657.338 | U22: =B22-S22 -> 354856.3 | V22: =V21+T22 -> 62582.324 | W22: =A22+Q22*$B$1 -> 7864.4075 | X22: =X21+$B$1 -> 420 | Y22: =Y21-B22+U22 -> 35256.3
A23: =W22 -> 7864.4075 | B23: =U22 -> 354856.3 | C23: =IF(A23<=11000,A23*Constants!$B$2+Constants!$B$1,216.7) -> 237.08135 | D23: =IF(A23<=11000, Constants!$B$4*(1-0.0065*Climb!A23/Constants!$B$1)^5.2561, 22632*EXP(9.81*(11000-A23)/Constants!$B$6/C23)) -> 36309.251 | E23: =D23/(Constants!$B$6*Climb!C23) -> 0.53362726 | F23: =SQRT(Constants!$B$8*Constants!$B$6*Climb!C23) -> 308.64103 | G23: =VLOOKUP(TRUNC(A23/1000),Flight!$A$3:$C$17,3,FALSE) -> 290 | H23: =SQRT(5*((Constants!$B$3/Climb!E23*((1+0.2*(Climb!G23/661.5)^2)^3.5-1)+1)^0.286-1)) -> 0.64641027 | I23: =H23*F23 -> 199.50873 | J23: =I23/Constants!$B$9 -> 387.81429 | K23: =2*B23*Constants!$B$7/(Climb!E23*Climb!$B$2*Climb!I23^2) -> 0.38791179 | L23: 0.02 | M23: =K23^2/(PI()*$B$3*$B$4)+L23 -> 0.027572544 | N23: =0.5*E23*Climb!I23^2*Climb!$B$2*Climb!M23 -> 247437.43 | O23: =($B$9-$B$10*H23)*(E23/Constants!$B$3)^$B$11 -> 101109.3 | P23: =O23*$B$13 -> 404437.2 | Q23: =(P23-N23)*I23/B23/Constants!$B$7 -> 8.9978637 | R23: =ASIN(Q23/I23) -> 0.045115402 | S23: =P23*$B$1*$B$12/Constants!$B$7 -> 395.77952 | T23: =I23*COS(R23)*$B$1 -> 11958.344 | U23: =B23-S23 -> 354460.52 | V23: =V22+T23 -> 74540.668 | W23: =A23+Q23*$B$1 -> 8404.2793 | X23: =X22+$B$1 -> 480 | Y23: =Y22-B23+U23 -> 34860.52
A24: =W23 -> 8404.2793 | B24: =U23 -> 354460.52 | C24: =IF(A24<=11000,A24*Constants!$B$2+Constants!$B$1,216.7) -> 233.57218 | D24: =IF(A24<=11000, Constants!$B$4*(1-0.0065*Climb!A24/Constants!$B$1)^5.2561, 22632*EXP(9.81*(11000-A24)/Constants!$B$6/C24)) -> 33572.012 | E24: =D24/(Constants!$B$6*Climb!C24) -> 0.50081156 | F24: =SQRT(Constants!$B$8*Constants!$B$6*Climb!C24) -> 306.34834 | G24: =VLOOKUP(TRUNC(A24/1000),Flight!$A$3:$C$17,3,FALSE) -> 290 | H24: =SQRT(5*((Constants!$B$3/Climb!E24*((1+0.2*(Climb!G24/661.5)^2)^3.5-1)+1)^0.286-1)) -> 0.66524381 | I24: =H24*F24 -> 203.79633 | J24: =I24/Constants!$B$9 -> 396.14872 | K24: =2*B24*Constants!$B$7/(Climb!E24*Climb!$B$2*Climb!I24^2) -> 0.39567908 | L24: 0.02 | M24: =K24^2/(PI()*$B$3*$B$4)+L24 -> 0.027878836 | N24: =0.5*E24*Climb!I24^2*Climb!$B$2*Climb!M24 -> 245001.32 | O24: =($B$9-$B$10*H24)*(E24/Constants!$B$3)^$B$11 -> 93731.785 | P24: =O24*$B$13 -> 374927.14 | Q24: =(P24-N24)*I24/B24/Constants!$B$7 -> 7.6147379 | R24: =ASIN(Q24/I24) -> 0.03737315 | S24: =P24*$B$1*$B$12/Constants!$B$7 -> 366.90118 | T24: =I24*COS(R24)*$B$1 -> 12219.241 | U24: =B24-S24 -> 354093.62 | V24: =V23+T24 -> 86759.909 | W24: =A24+Q24*$B$1 -> 8861.1636 | X24: =X23+$B$1 -> 540 | Y24: =Y23-B24+U24 -> 34493.619
A25: =W24 -> 8861.1636 | B25: =U24 -> 354093.62 | C25: =IF(A25<=11000,A25*Constants!$B$2+Constants!$B$1,216.7) -> 230.60244 | D25: =IF(A25<=11000, Constants!$B$4*(1-0.0065*Climb!A25/Constants!$B$1)^5.2561, 22632*EXP(9.81*(11000-A25)/Constants!$B$6/C25)) -> 31388.315 | E25: =D25/(Constants!$B$6*Climb!C25) -> 0.47426625 | F25: =SQRT(Constants!$B$8*Constants!$B$6*Climb!C25) -> 304.39458 | G25: =VLOOKUP(TRUNC(A25/1000),Flight!$A$3:$C$17,3,FALSE) -> 290 | H25: =SQRT(5*((Constants!$B$3/Climb!E25*((1+0.2*(Climb!G25/661.5)^2)^3.5-1)+1)^0.286-1)) -> 0.68175692 | I25: =H25*F25 -> 207.52311 | J25: =I25/Constants!$B$9 -> 403.393 | K25: =2*B25*Constants!$B$7/(Climb!E25*Climb!$B$2*Climb!I25^2) -> 0.40253648 | L25: 0.02 | M25: =K25^2/(PI()*$B$3*$B$4)+L25 -> 0.028154294 | N25: =0.5*E25*Climb!I25^2*Climb!$B$2*Climb!M25 -> 242955.37 | O25: =($B$9-$B$10*H25)*(E25/Constants!$B$3)^$B$11 -> 87791.373 | P25: =O25*$B$13 -> 351165.49 | Q25: =(P25-N25)*I25/B25/Constants!$B$7 -> 6.4646833 | R25: =ASIN(Q25/I25) -> 0.031156671 | S25: =P25*$B$1*$B$12/Constants!$B$7 -> 343.64819 | T25: =I25*COS(R25)*$B$1 -> 12445.344 | U25: =B25-S25 -> 353749.97 | V25: =V24+T25 -> 99205.253 | W25: =A25+Q25*$B$1 -> 9249.0446 | X25: =X24+$B$1 -> 600 | Y25: =Y24-B25+U25 -> 34149.971
A26: =W25 -> 9249.0446 | B26: =U25 -> 353749.97 | C26: =IF(A26<=11000,A26*Constants!$B$2+Constants!$B$1,216.7) -> 228.08121 | D26: =IF(A26<=11000, Constants!$B$4*(1-0.0065*Climb!A26/Constants!$B$1)^5.2561, 22632*EXP(9.81*(11000-A26)/Constants!$B$6/C26)) -> 29626.024 | E26: =D26/(Constants!$B$6*Climb!C26) -> 0.45258688 | F26: =SQRT(Constants!$B$8*Constants!$B$6*Climb!C26) -> 302.726 | G26: =VLOOKUP(TRUNC(A26/1000),Flight!$A$3:$C$17,3,FALSE) -> 290 | H26: =SQRT(5*((Constants!$B$3/Climb!E26*((1+0.2*(Climb!G26/661.5)^2)^3.5-1)+1)^0.286-1)) -> 0.69620496 | I26: =H26*F26 -> 210.75934 | J26: =I26/Constants!$B$9 -> 409.68374 | K26: =2*B26*Constants!$B$7/(Climb!E26*Climb!$B$2*Climb!I26^2) -> 0.40856681 | L26: 0.02 | M26: =K26^2/(PI()*$B$3*$B$4)+L26 -> 0.02840044 | N26: =0.5*E26*Climb!I26^2*Climb!$B$2*Climb!M26 -> 241227.83 | O26: =($B$9-$B$10*H26)*(E26/Constants!$B$3)^$B$11 -> 82960.068 | P26: =O26*$B$13 -> 331840.27 | Q26: =(P26-N26)*I26/B26/Constants!$B$7 -> 5.5031235 | R26: =ASIN(Q26/I26) -> 0.026113903 | S26: =P26*$B$1*$B$12/Constants!$B$7 -> 324.73666 | T26: =I26*COS(R26)*$B$1 -> 12641.249 | U26: =B26-S26 -> 353425.23 | V26: =V25+T26 -> 111846.5 | W26: =A26+Q26*$B$1 -> 9579.232 | X26: =X25+$B$1 -> 660 | Y26: =Y25-B26+U26 -> 33825.234
A27: =W26 -> 9579.232 | B27: =U26 -> 353425.23 | C27: =IF(A27<=11000,A27*Constants!$B$2+Constants!$B$1,216.7) -> 225.93499 | D27: =IF(A27<=11000, Constants!$B$4*(1-0.0065*Climb!A27/Constants!$B$1)^5.2561, 22632*EXP(9.81*(11000-A27)/Constants!$B$6/C27)) -> 28189.785 | E27: =D27/(Constants!$B$6*Climb!C27) -> 0.43473677 | F27: =SQRT(Constants!$B$8*Constants!$B$6*Climb!C27) -> 301.29832 | G27: =VLOOKUP(TRUNC(A27/1000),Flight!$A$3:$C$17,3,FALSE) -> 290 | H27: =SQRT(5*((Constants!$B$3/Climb!E27*((1+0.2*(Climb!G27/661.5)^2)^3.5-1)+1)^0.286-1)) -> 0.70882412 | I27: =H27*F27 -> 213.56752 | J27: =I27/Constants!$B$9 -> 415.14241 | K27: =2*B27*Constants!$B$7/(Climb!E27*Climb!$B$2*Climb!I27^2) -> 0.4138501 | L27: 0.02 | M27: =K27^2/(PI()*$B$3*$B$4)+L27 -> 0.028619102 | N27: =0.5*E27*Climb!I27^2*Climb!$B$2*Climb!M27 -> 239761.52 | O27: =($B$9-$B$10*H27)*(E27/Constants!$B$3)^$B$11 -> 78997.005 | P27: =O27*$B$13 -> 315988.02 | Q27: =(P27-N27)*I27/B27/Constants!$B$7 -> 4.6954216 | R27: =ASIN(Q27/I27) -> 0.021987426 | S27: =P27*$B$1*$B$12/Constants!$B$7 -> 309.22375 | T27: =I27*COS(R27)*$B$1 -> 12810.954 | U27: =B27-S27 -> 353116.01 | V27: =V26+T27 -> 124657.46 | W27: =A27+Q27*$B$1 -> 9860.9573 | X27: =X26+$B$1 -> 720 | Y27: =Y26-B27+U27 -> 33516.011
A28: =W27 -> 9860.9573 | B28: =U27 -> 353116.01 | C28: =IF(A28<=11000,A28*Constants!$B$2+Constants!$B$1,216.7) -> 224.10378 | D28: =IF(A28<=11000, Constants!$B$4*(1-0.0065*Climb!A28/Constants!$B$1)^5.2561, 22632*EXP(9.81*(11000-A28)/Constants!$B$6/C28)) -> 27009.405 | E28: =D28/(Constants!$B$6*Climb!C28) -> 0.41993681 | F28: =SQRT(Constants!$B$8*Constants!$B$6*Climb!C28) -> 300.07482 | G28: =VLOOKUP(TRUNC(A28/1000),Flight!$A$3:$C$17,3,FALSE) -> 290 | H28: =SQRT(5*((Constants!$B$3/Climb!E28*((1+0.2*(Climb!G28/661.5)^2)^3.5-1)+1)^0.286-1)) -> 0.71983014 | I28: =H28*F28 -> 216.0029 | J28: =I28/Constants!$B$9 -> 419.87641 | K28: =2*B28*Constants!$B$7/(Climb!E28*Climb!$B$2*Climb!I28^2) -> 0.41846254 | L28: 0.02 | M28: =K28^2/(PI()*$B$3*$B$4)+L28 -> 0.028812295 | N28: =0.5*E28*Climb!I28^2*Climb!$B$2*Climb!M28 -> 238510.6 | O28: =($B$9-$B$10*H28)*(E28/Constants!$B$3)^$B$11 -> 75722.128 | P28: =O28*$B$13 -> 302888.51 | Q28: =(P28-N28)*I28/B28/Constants!$B$7 -> 4.0143021 | R28: =ASIN(Q28/I28) -> 0.018585552 | S28: =P28*$B$1*$B$12/Constants!$B$7 -> 296.40466 | T28: =I28*COS(R28)*$B$1 -> 12957.936 | U28: =B28-S28 -> 352819.61 | V28: =V27+T28 -> 137615.39 | W28: =A28+Q28*$B$1 -> 10101.815 | X28: =X27+$B$1 -> 780 | Y28: =Y27-B28+U28 -> 33219.606
... A40: =W39 -> 10999.29 | B40: =U39 -> 349985.96 | C40: =IF(A40<=11000,A40*Constants!$B$2+Constants!$B$1,216.7) -> 216.70462 | D40: =IF(A40<=11000, Constants!$B$4*(1-0.0065*Climb!A40/Constants!$B$1)^5.2561, 22632*EXP(9.81*(11000-A40)/Constants!$B$6/C40)) -> 22639.965 | E40: =D40/(Constants!$B$6*Climb!C40) -> 0.36402038 | F40: =SQRT(Constants!$B$8*Constants!$B$6*Climb!C40) -> 295.07951 | G40: =VLOOKUP(TRUNC(A40/1000),Flight!$A$3:$C$17,3,FALSE) -> 300 | H40: =SQRT(5*((Constants!$B$3/Climb!E40*((1+0.2*(Climb!G40/661.5)^2)^3.5-1)+1)^0.286-1)) -> 0.79080427 | I40: =H40*F40 -> 233.35013 | J40: =I40/Constants!$B$9 -> 453.59676 | K40: =2*B40*Constants!$B$7/(Climb!E40*Climb!$B$2*Climb!I40^2) -> 0.40996909 | L40: 0.0204 | M40: =K40^2/(PI()*$B$3*$B$4)+L40 -> 0.028858203 | N40: =0.5*E40*Climb!I40^2*Climb!$B$2*Climb!M40 -> 241678.38 | O40: =($B$9-$B$10*H40)*(E40/Constants!$B$3)^$B$11 -> 62128.914 | P40: =O40*$B$13 -> 248515.66 | Q40: =(P40-N40)*I40/B40/Constants!$B$7 -> 0.464699 | R40: =ASIN(Q40/I40) -> 0.0019914251 | S40: =P40*$B$1*$B$12/Constants!$B$7 -> 243.19575 | T40: =I40*COS(R40)*$B$1 -> 14000.98 | U40: =B40-S40 -> 349742.77 | V40: =V39+T40 -> 303436.7 | W40: =A40+Q40*$B$1 -> 11027.172 | X40: =X39+$B$1 -> 1500 | Y40: =Y39-B40+U40 -> 30142.766
A41: =W40 -> 11027.172 | B41: =U40 -> 349742.77 | C41: =IF(A41<=11000,A41*Constants!$B$2+Constants!$B$1,216.7) -> 216.7 | D41: =IF(A41<=11000, Constants!$B$4*(1-0.0065*Climb!A41/Constants!$B$1)^5.2561, 22632*EXP(9.81*(11000-A41)/Constants!$B$6/C41)) -> 22535.208 | E41: =D41/(Constants!$B$6*Climb!C41) -> 0.36234375 | F41: =SQRT(Constants!$B$8*Constants!$B$6*Climb!C41) -> 295.07636 | G41: 300 | H41: =SQRT(5*((Constants!$B$3/Climb!E41*((1+0.2*(Climb!G41/661.5)^2)^3.5-1)+1)^0.286-1)) -> 0.79239138 | I41: =H41*F41 -> 233.81597 | J41: =I41/Constants!$B$9 -> 454.50227 | K41: =2*B41*Constants!$B$7/(Climb!E41*Climb!$B$2*Climb!I41^2) -> 0.40994154 | L41: 0.0204 | M41: =K41^2/(PI()*$B$3*$B$4)+L41 -> 0.028857066 | N41: =0.5*E41*Climb!I41^2*Climb!$B$2*Climb!M41 -> 241517.16 | O41: =($B$9-$B$10*H41)*(E41/Constants!$B$3)^$B$11 -> 61767.647 | P41: =O41*$B$13 -> 247070.59 | Q41: =(P41-N41)*I41/B41/Constants!$B$7 -> 0.37845804 | R41: =ASIN(Q41/I41) -> 0.0016186158 | S41: =P41*$B$1*$B$12/Constants!$B$7 -> 241.78162 | T41: =I41*COS(R41)*$B$1 -> 14028.94 | U41: =B41-S41 -> 349500.98 | V41: =V40+T41 -> 317465.64 | W41: =A41+Q41*$B$1 -> 11049.879 | X41: =X40+$B$1 -> 1560 | Y41: =Y40-B41+U41 -> 29900.984
A42: =W41 -> 11049.879 | B42: =U41 -> 349500.98 | C42: =IF(A42<=11000,A42*Constants!$B$2+Constants!$B$1,216.7) -> 216.7 | D42: =IF(A42<=11000, Constants!$B$4*(1-0.0065*Climb!A42/Constants!$B$1)^5.2561, 22632*EXP(9.81*(11000-A42)/Constants!$B$6/C42)) -> 22454.637 | E42: =D42/(Constants!$B$6*Climb!C42) -> 0.36104824 | F42: =SQRT(Constants!$B$8*Constants!$B$6*Climb!C42) -> 295.07636 | G42: =VLOOKUP(TRUNC(A42/1000),Flight!$A$3:$C$17,3,FALSE) -> 300 | H42: =SQRT(5*((Constants!$B$3/Climb!E42*((1+0.2*(Climb!G42/661.5)^2)^3.5-1)+1)^0.286-1)) -> 0.7936244 | I42: =H42*F42 -> 234.1798 | J42: =I42/Constants!$B$9 -> 455.20951 | K42: =2*B42*Constants!$B$7/(Climb!E42*Climb!$B$2*Climb!I42^2) -> 0.40985157 | L42: 0.0204 | M42: =K42^2/(PI()*$B$3*$B$4)+L42 -> 0.028853354 | N42: =0.5*E42*Climb!I42^2*Climb!$B$2*Climb!M42 -> 241372.13 | O42: =($B$9-$B$10*H42)*(E42/Constants!$B$3)^$B$11 -> 61488.63 | P42: =O42*$B$13 -> 245954.52 | Q42: =(P42-N42)*I42/B42/Constants!$B$7 -> 0.3129858 | R42: =ASIN(Q42/I42) -> 0.0013365196 | S42: =P42*$B$1*$B$12/Constants!$B$7 -> 240.68944 | T42: =I42*COS(R42)*$B$1 -> 14050.775 | U42: =B42-S42 -> 349260.3 | V42: =V41+T42 -> 331516.41 | W42: =A42+Q42*$B$1 -> 11068.658 | X42: =X41+$B$1 -> 1620 | Y42: =Y41-B42+U42 -> 29660.295
A43: =W42 -> 11068.658 | B43: =U42 -> 349260.3 | C43: =IF(A43<=11000,A43*Constants!$B$2+Constants!$B$1,216.7) -> 216.7 | D43: =IF(A43<=11000, Constants!$B$4*(1-0.0065*Climb!A43/Constants!$B$1)^5.2561, 22632*EXP(9.81*(11000-A43)/Constants!$B$6/C43)) -> 22388.222 | E43: =D43/(Constants!$B$6*Climb!C43) -> 0.35998035 | F43: =SQRT(Constants!$B$8*Constants!$B$6*Climb!C43) -> 295.07636 | G43: =VLOOKUP(TRUNC(A43/1000),Flight!$A$3:$C$17,3,FALSE) -> 300 | H43: =SQRT(5*((Constants!$B$3/Climb!E43*((1+0.2*(Climb!G43/661.5)^2)^3.5-1)+1)^0.286-1)) -> 0.79464518 | I43: =H43*F43 -> 234.48101 | J43: =I43/Constants!$B$9 -> 455.79501 | K43: =2*B43*Constants!$B$7/(Climb!E43*Climb!$B$2*Climb!I43^2) -> 0.40972962 | L43: 0.0204 | M43: =K43^2/(PI()*$B$3*$B$4)+L43 -> 0.028848325 | N43: =0.5*E43*Climb!I43^2*Climb!$B$2*Climb!M43 -> 241235.63 | O43: =($B$9-$B$10*H43)*(E43/Constants!$B$3)^$B$11 -> 61258.722 | P43: =O43*$B$13 -> 245034.89 | Q43: =(P43-N43)*I43/B43/Constants!$B$7 -> 0.26000873 | R43: =ASIN(Q43/I43) -> 0.0011088692 | S43: =P43*$B$1*$B$12/Constants!$B$7 -> 239.78949 | T43: =I43*COS(R43)*$B$1 -> 14068.852 | U43: =B43-S43 -> 349020.51 | V43: =V42+T43 -> 345585.27 | W43: =A43+Q43*$B$1 -> 11084.259 | X43: =X42+$B$1 -> 1680 | Y43: =Y42-B43+U43 -> 29420.506
A44: =W43 -> 11084.259 | B44: =U43 -> 349020.51 | C44: =IF(A44<=11000,A44*Constants!$B$2+Constants!$B$1,216.7) -> 216.7 | D44: =IF(A44<=11000, Constants!$B$4*(1-0.0065*Climb!A44/Constants!$B$1)^5.2561, 22632*EXP(9.81*(11000-A44)/Constants!$B$6/C44)) -> 22333.198 | E44: =D44/(Constants!$B$6*Climb!C44) -> 0.35909561 | F44: =SQRT(Constants!$B$8*Constants!$B$6*Climb!C44) -> 295.07636 | G44: =VLOOKUP(TRUNC(A44/1000),Flight!$A$3:$C$17,3,FALSE) -> 300 | H44: =SQRT(5*((Constants!$B$3/Climb!E44*((1+0.2*(Climb!G44/661.5)^2)^3.5-1)+1)^0.286-1)) -> 0.79549393 | I44: =H44*F44 -> 234.73146 | J44: =I44/Constants!$B$9 -> 456.28184 | K44: =2*B44*Constants!$B$7/(Climb!E44*Climb!$B$2*Climb!I44^2) -> 0.40958171 | L44: 0.0204 | M44: =K44^2/(PI()*$B$3*$B$4)+L44 -> 0.028842226 | N44: =0.5*E44*Climb!I44^2*Climb!$B$2*Climb!M44 -> 241106.09 | O44: =($B$9-$B$10*H44)*(E44/Constants!$B$3)^$B$11 -> 61068.304 | P44: =O44*$B$13 -> 244273.22 | Q44: =(P44-N44)*I44/B44/Constants!$B$7 -> 0.21712871 | R44: =ASIN(Q44/I44) -> 0.00092500913 | S44: =P44*$B$1*$B$12/Constants!$B$7 -> 239.04413 | T44: =I44*COS(R44)*$B$1 -> 14083.881 | U44: =B44-S44 -> 348781.46 | V44: =V43+T44 -> 359669.15 | W44: =A44+Q44*$B$1 -> 11097.287 | X44: =X43+$B$1 -> 1740 | Y44: =Y43-B44+U44 -> 29181.461
A45: =W44 -> 11097.287 | B45: =U44 -> 348781.46 | C45: =IF(A45<=11000,A45*Constants!$B$2+Constants!$B$1,216.7) -> 216.7 | D45: =IF(A45<=11000, Constants!$B$4*(1-0.0065*Climb!A45/Constants!$B$1)^5.2561, 22632*EXP(9.81*(11000-A45)/Constants!$B$6/C45)) -> 22287.352 | E45: =D45/(Constants!$B$6*Climb!C45) -> 0.35835846 | F45: =SQRT(Constants!$B$8*Constants!$B$6*Climb!C45) -> 295.07636 | G45: =VLOOKUP(TRUNC(A45/1000),Flight!$A$3:$C$17,3,FALSE) -> 300 | H45: =SQRT(5*((Constants!$B$3/Climb!E45*((1+0.2*(Climb!G45/661.5)^2)^3.5-1)+1)^0.286-1)) -> 0.79620322 | I45: =H45*F45 -> 234.94075 | J45: =I45/Constants!$B$9 -> 456.68868 | K45: =2*B45*Constants!$B$7/(Climb!E45*Climb!$B$2*Climb!I45^2) -> 0.40941271 | L45: 0.0204 | M45: =K45^2/(PI()*$B$3*$B$4)+L45 -> 0.028835261 | N45: =0.5*E45*Climb!I45^2*Climb!$B$2*Climb!M45 -> 240982.2 | O45: =($B$9-$B$10*H45)*(E45/Constants!$B$3)^$B$11 -> 60909.689 | P45: =O45*$B$13 -> 243638.76 | Q45: =(P45-N45)*I45/B45/Constants!$B$7 -> 0.18241283 | R45: =ASIN(Q45/I45) -> 0.00077642064 | S45: =P45*$B$1*$B$12/Constants!$B$7 -> 238.42325 | T45: =I45*COS(R45)*$B$1 -> 14096.441 | U45: =B45-S45 -> 348543.04 | V45: =V44+T45 -> 373765.59 | W45: =A45+Q45*$B$1 -> 11108.231 | X45: =X44+$B$1 -> 1800 | Y45: =Y44-B45+U45 -> 28943.038
A46: =W45 -> 11108.231 | B46: =U45 -> 348543.04 | C46: =IF(A46<=11000,A46*Constants!$B$2+Constants!$B$1,216.7) -> 216.7 | D46: =IF(A46<=11000, Constants!$B$4*(1-0.0065*Climb!A46/Constants!$B$1)^5.2561, 22632*EXP(9.81*(11000-A46)/Constants!$B$6/C46)) -> 22248.909 | E46: =D46/(Constants!$B$6*Climb!C46) -> 0.35774033 | F46: =SQRT(Constants!$B$8*Constants!$B$6*Climb!C46) -> 295.07636 | G46: =VLOOKUP(TRUNC(A46/1000),Flight!$A$3:$C$17,3,FALSE) -> 300 | H46: =SQRT(5*((Constants!$B$3/Climb!E46*((1+0.2*(Climb!G46/661.5)^2)^3.5-1)+1)^0.286-1)) -> 0.79679947 | I46: =H46*F46 -> 235.11669 | J46: =I46/Constants!$B$9 -> 457.03068 | K46: =2*B46*Constants!$B$7/(Climb!E46*Climb!$B$2*Climb!I46^2) -> 0.40922663 | L46: 0.0204 | M46: =K46^2/(PI()*$B$3*$B$4)+L46 -> 0.028827595 | N46: =0.5*E46*Climb!I46^2*Climb!$B$2*Climb!M46 -> 240862.92 | O46: =($B$9-$B$10*H46)*(E46/Constants!$B$3)^$B$11 -> 60776.715 | P46: =O46*$B$13 -> 243106.86 | Q46: =(P46-N46)*I46/B46/Constants!$B$7 -> 0.15430133 | R46: =ASIN(Q46/I46) -> 0.00065627559 | S46: =P46*$B$1*$B$12/Constants!$B$7 -> 237.90274 | T46: =I46*COS(R46)*$B$1 -> 14106.998 | U46: =B46-S46 -> 348305.14 | V46: =V45+T46 -> 387872.59 | W46: =A46+Q46*$B$1 -> 11117.489 | X46: =X45+$B$1 -> 1860 | Y46: =Y45-B46+U46 -> 28705.135
A47: =W46 -> 11117.489 | B47: =U46 -> 348305.14 | C47: =IF(A47<=11000,A47*Constants!$B$2+Constants!$B$1,216.7) -> 216.7 | D47: =IF(A47<=11000, Constants!$B$4*(1-0.0065*Climb!A47/Constants!$B$1)^5.2561, 22632*EXP(9.81*(11000-A47)/Constants!$B$6/C47)) -> 22216.442 | E47: =D47/(Constants!$B$6*Climb!C47) -> 0.35721829 | F47: =SQRT(Constants!$B$8*Constants!$B$6*Climb!C47) -> 295.07636 | G47: =VLOOKUP(TRUNC(A47/1000),Flight!$A$3:$C$17,3,FALSE) -> 300 | H47: =SQRT(5*((Constants!$B$3/Climb!E47*((1+0.2*(Climb!G47/661.5)^2)^3.5-1)+1)^0.286-1)) -> 0.79730409 | I47: =H47*F47 -> 235.26559 | J47: =I47/Constants!$B$9 -> 457.32012 | K47: =2*B47*Constants!$B$7/(Climb!E47*Climb!$B$2*Climb!I47^2) -> 0.40902669 | L47: 0.0204 | M47: =K47^2/(PI()*$B$3*$B$4)+L47 -> 0.028819362 | N47: =0.5*E47*Climb!I47^2*Climb!$B$2*Climb!M47 -> 240747.39 | O47: =($B$9-$B$10*H47)*(E47/Constants!$B$3)^$B$11 -> 60664.432 | P47: =O47*$B$13 -> 242657.73 | Q47: =(P47-N47)*I47/B47/Constants!$B$7 -> 0.13153442 | R47: =ASIN(Q47/I47) -> 0.00055908908 | S47: =P47*$B$1*$B$12/Constants!$B$7 -> 237.46322 | T47: =I47*COS(R47)*$B$1 -> 14115.933 | U47: =B47-S47 -> 348067.67 | V47: =V46+T47 -> 401988.52 | W47: =A47+Q47*$B$1 -> 11125.382 | X47: =X46+$B$1 -> 1920 | Y47: =Y46-B47+U47 -> 28467.672
A48: =W47 -> 11125.382 | B48: =U47 -> 348067.67 | C48: =IF(A48<=11000,A48*Constants!$B$2+Constants!$B$1,216.7) -> 216.7 | D48: =IF(A48<=11000, Constants!$B$4*(1-0.0065*Climb!A48/Constants!$B$1)^5.2561, 22632*EXP(9.81*(11000-A48)/Constants!$B$6/C48)) -> 22188.803 | E48: =D48/(Constants!$B$6*Climb!C48) -> 0.35677389 | F48: =SQRT(Constants!$B$8*Constants!$B$6*Climb!C48) -> 295.07636 | G48: =VLOOKUP(TRUNC(A48/1000),Flight!$A$3:$C$17,3,FALSE) -> 300 | H48: =SQRT(5*((Constants!$B$3/Climb!E48*((1+0.2*(Climb!G48/661.5)^2)^3.5-1)+1)^0.286-1)) -> 0.79773444 | I48: =H48*F48 -> 235.39258 | J48: =I48/Constants!$B$9 -> 457.56696 | K48: =2*B48*Constants!$B$7/(Climb!E48*Climb!$B$2*Climb!I48^2) -> 0.40881554 | L48: 0.0204 | M48: =K48^2/(PI()*$B$3*$B$4)+L48 -> 0.028810671 | N48: =0.5*E48*Climb!I48^2*Climb!$B$2*Climb!M48 -> 240634.94 | O48: =($B$9-$B$10*H48)*(E48/Constants!$B$3)^$B$11 -> 60568.861 | P48: =O48*$B$13 -> 242275.44 | Q48: =(P48-N48)*I48/B48/Constants!$B$7 -> 0.1130938 | R48: =ASIN(Q48/I48) -> 0.00048044763 | S48: =P48*$B$1*$B$12/Constants!$B$7 -> 237.08912 | T48: =I48*COS(R48)*$B$1 -> 14123.553 | U48: =B48-S48 -> 347830.58 | V48: =V47+T48 -> 416112.07 | W48: =A48+Q48*$B$1 -> 11132.167 | X48: =X47+$B$1 -> 1980 | Y48: =Y47-B48+U48 -> 28230.583
A49: =W48 -> 11132.167 | B49: =U48 -> 347830.58 | C49: =IF(A49<=11000,A49*Constants!$B$2+Constants!$B$1,216.7) -> 216.7 | D49: =IF(A49<=11000, Constants!$B$4*(1-0.0065*Climb!A49/Constants!$B$1)^5.2561, 22632*EXP(9.81*(11000-A49)/Constants!$B$6/C49)) -> 22165.066 | E49: =D49/(Constants!$B$6*Climb!C49) -> 0.35639222 | F49: =SQRT(Constants!$B$8*Constants!$B$6*Climb!C49) -> 295.07636 | G49: =VLOOKUP(TRUNC(A49/1000),Flight!$A$3:$C$17,3,FALSE) -> 300 | H49: =SQRT(5*((Constants!$B$3/Climb!E49*((1+0.2*(Climb!G49/661.5)^2)^3.5-1)+1)^0.286-1)) -> 0.7981046 | I49: =H49*F49 -> 235.5018 | J49: =I49/Constants!$B$9 -> 457.77928 | K49: =2*B49*Constants!$B$7/(Climb!E49*Climb!$B$2*Climb!I49^2) -> 0.4085953 | L49: 0.0204 | M49: =K49^2/(PI()*$B$3*$B$4)+L49 -> 0.028801612 | N49: =0.5*E49*Climb!I49^2*Climb!$B$2*Climb!M49 -> 240524.98 | O49: =($B$9-$B$10*H49)*(E49/Constants!$B$3)^$B$11 -> 60486.795 | P49: =O49*$B$13 -> 241947.18 | Q49: =(P49-N49)*I49/B49/Constants!$B$7 -> 0.098155951 | R49: =ASIN(Q49/I49) -> 0.00041679491 | S49: =P49*$B$1*$B$12/Constants!$B$7 -> 236.76788 | T49: =I49*COS(R49)*$B$1 -> 14130.107 | U49: =B49-S49 -> 347593.82 | V49: =V48+T49 -> 430242.18 | W49: =A49+Q49*$B$1 -> 11138.057 | X49: =X48+$B$1 -> 2040 | Y49: =Y48-B49+U49 -> 27993.815
A50: =W49 -> 11138.057 | B50: =U49 -> 347593.82 | C50: =IF(A50<=11000,A50*Constants!$B$2+Constants!$B$1,216.7) -> 216.7 | D50: =IF(A50<=11000, Constants!$B$4*(1-0.0065*Climb!A50/Constants!$B$1)^5.2561, 22632*EXP(9.81*(11000-A50)/Constants!$B$6/C50)) -> 22144.485 | E50: =D50/(Constants!$B$6*Climb!C50) -> 0.3560613 | F50: =SQRT(Constants!$B$8*Constants!$B$6*Climb!C50) -> 295.07636 | G50: =VLOOKUP(TRUNC(A50/1000),Flight!$A$3:$C$17,3,FALSE) -> 300 | H50: =SQRT(5*((Constants!$B$3/Climb!E50*((1+0.2*(Climb!G50/661.5)^2)^3.5-1)+1)^0.286-1)) -> 0.79842597 | I50: =H50*F50 -> 235.59663 | J50: =I50/Constants!$B$9 -> 457.96361 | K50: =2*B50*Constants!$B$7/(Climb!E50*Climb!$B$2*Climb!I50^2) -> 0.40836772 | L50: 0.0204 | M50: =K50^2/(PI()*$B$3*$B$4)+L50 -> 0.028792255 | N50: =0.5*E50*Climb!I50^2*Climb!$B$2*Climb!M50 -> 240417.08 | O50: =($B$9-$B$10*H50)*(E50/Constants!$B$3)^$B$11 -> 60415.647 | P50: =O50*$B$13 -> 241662.59 | Q50: =(P50-N50)*I50/B50/Constants!$B$7 -> 0.08605453 | R50: =ASIN(Q50/I50) -> 0.00036526215 | S50: =P50*$B$1*$B$12/Constants!$B$7 -> 236.48938 | T50: =I50*COS(R50)*$B$1 -> 14135.797 | U50: =B50-S50 -> 347357.33 | V50: =V49+T50 -> 444377.98 | W50: =A50+Q50*$B$1 -> 11143.22 | X50: =X49+$B$1 -> 2100 | Y50: =Y49-B50+U50 -> 27757.326

Sheet Cruise
A1: Time step | B1: 120 | C1: s
A2: Wing area | B2: 858 | C2: m^2
A3: Aspect ratio | B3: 9
A4: e | B4: 0.84
A5: Empty weight | B5: 276800 | C5: kg
A6: Payload | B6: 42800 | C6: Kg
A7: Fuel | B7: 42475 | C7: l | D7: Fuel | E7: =B7*0.804 -> 34149.9 | F7: kg | H7: Fuel | I7: 34150 | J7: kg | K7: => | L7: Fuel | M7: =I7/0.804 -> 42475.124 | N7: l
A8: Thrust | B8: 0 | C8: 0.9 | D8: Velocity (M)
B9: 338000 | C9: 180000 | D9: Thrust (N)
A10: Lambda | B10: =(B9-C9)/C8 -> 175555.56
A11: Thrust laps rate | B11: 0.96
A12: TSFC | B12: 0.00016 | C12: N/N/S
A13: Num Engines | B13: 4
A15: Altitude | B15: Mass | C15: Temperature | D15: Preassure | E15: Air density | F15: Speed of sound | G15: IAS | H15: Mtrue | I15: TAS (m/s) | J15: TAS (Knot) | K15: Lift coef. | L15: Cdrag_0 | M15: Drag coef. | N15: Drag | O15: Thrust | P15: Total Thrust | Q15: dh/dt | R15: Climbing angle | S15: dW/dt | T15: Distance | U15: New mass | V15: Cumulative distance | W15: Cumulative altitude | X15: Flight time | Y15: Remaining Fuel
A16: 9249 | B16: =B5+B6+E7 -> 353749.9 | C16: =IF(A16<=11000,A16*Constants!$B$2+Constants!$B$1,216.7) -> 228.0815 | D16: =IF(A16<=11000, Constants!$B$4*(1-0.0065*A16/Constants!$B$1)^5.2561, 22632*EXP(9.81*(11000-A16)/Constants!$B$6/C16)) -> 29626.222 | E16: =D16/(Constants!$B$6*Cruise!C16) -> 0.45258933 | F16: =SQRT(Constants!$B$8*Constants!$B$6*Cruise!C16) -> 302.72619 | G16: 290 | H16: =SQRT(5*((Constants!$B$3/Cruise!E16*((1+0.2*(Cruise!G16/661.5)^2)^3.5-1)+1)^0.286-1)) -> 0.69620327 | I16: =H16*F16 -> 210.75897 | J16: =I16/Constants!$B$9 -> 409.68301 | K16: =2*B16*Constants!$B$7/(Cruise!E16*Cruise!$B$2*Cruise!I16^2) -> 0.40237558 | L16: 0.02 | M16: =K16^2/(PI()*$B$3*$B$4)+L16 -> 0.026816973 | N16: =0.5*E16*Cruise!I16^2*Cruise!$B$2*Cruise!M16 -> 231282.87 | O16: =P16/$B$13 -> 57820.718 | P16: =N16 -> 231282.87 | Q16: =(P16-N16)*I16/B16/Constants!$B$7 -> 0 | R16: =ASIN(Q16/I16) -> 0 | S16: =P16*$B$1*$B$12/Constants!$B$7 -> 452.66372 | T16: =I16*COS(R16)*$B$1 -> 25291.076 | U16: =B16-S16 -> 353297.24 | V16: =T16 -> 25291.076 | W16: =A16+Q16*$B$1 -> 9249 | X16: =$B$1 -> 120 | Y16: =$E$7-B16+U16 -> 33697.236
A17: =W16 -> 9249 | B17: =U16 -> 353297.24 | C17: =IF(A17<=11000,A17*Constants!$B$2+Constants!$B$1,216.7) -> 228.0815 | D17: =IF(A17<=11000, Constants!$B$4*(1-0.0065*A17/Constants!$B$1)^5.2561, 22632*EXP(9.81*(11000-A17)/Constants!$B$6/C17)) -> 29626.222 | E17: =D17/(Constants!$B$6*Cruise!C17) -> 0.45258933 | F17: =SQRT(Constants!$B$8*Constants!$B$6*Cruise!C17) -> 302.72619 | G17: 290 | H17: =SQRT(5*((Constants!$B$3/Cruise!E17*((1+0.2*(Cruise!G17/661.5)^2)^3.5-1)+1)^0.286-1)) -> 0.69620327 | I17: =H17*F17 -> 210.75897 | J17: =I17/Constants!$B$9 -> 409.68301 | K17: =2*B17*Constants!$B$7/(Cruise!E17*Cruise!$B$2*Cruise!I17^2) -> 0.40186069 | L17: 0.02 | M17: =K17^2/(PI()*$B$3*$B$4)+L17 -> 0.026799538 | N17: =0.5*E17*Cruise!I17^2*Cruise!$B$2*Cruise!M17 -> 231132.5 | O17: =P17/$B$13 -> 57783.126 | P17: =N17 -> 231132.5 | Q17: =(P17-N17)*I17/B17/Constants!$B$7 -> 0 | R17: =ASIN(Q17/I17) -> 0 | S17: =P17*$B$1*$B$12/Constants!$B$7 -> 452.36942 | T17: =I17*COS(R17)*$B$1 -> 25291.076 | U17: =B17-S17 -> 352844.87 | V17: =V16+T17 -> 50582.152 | W17: =A17+Q17*$B$1 -> 9249 | X17: =X16+$B$1 -> 240 | Y17: =Y16-B17+U17 -> 33244.867
A18: =W17 -> 9249 | B18: =U17 -> 352844.87 | C18: =IF(A18<=11000,A18*Constants!$B$2+Constants!$B$1,216.7) -> 228.0815 | D18: =IF(A18<=11000, Constants!$B$4*(1-0.0065*A18/Constants!$B$1)^5.2561, 22632*EXP(9.81*(11000-A18)/Constants!$B$6/C18)) -> 29626.222 | E18: =D18/(Constants!$B$6*Cruise!C18) -> 0.45258933 | F18: =SQRT(Constants!$B$8*Constants!$B$6*Cruise!C18) -> 302.72619 | G18: 290 | H18: =SQRT(5*((Constants!$B$3/Cruise!E18*((1+0.2*(Cruise!G18/661.5)^2)^3.5-1)+1)^0.286-1)) -> 0.69620327 | I18: =H18*F18 -> 210.75897 | J18: =I18/Constants!$B$9 -> 409.68301 | K18: =2*B18*Constants!$B$7/(Cruise!E18*Cruise!$B$2*Cruise!I18^2) -> 0.40134614 | L18: 0.02 | M18: =K18^2/(PI()*$B$3*$B$4)+L18 -> 0.026782136 | N18: =0.5*E18*Cruise!I18^2*Cruise!$B$2*Cruise!M18 -> 230982.42 | O18: =P18/$B$13 -> 57745.606 | P18: =N18 -> 230982.42 | Q18: =(P18-N18)*I18/B18/Constants!$B$7 -> 0 | R18: =ASIN(Q18/I18) -> 0 | S18: =P18*$B$1*$B$12/Constants!$B$7 -> 452.07569 | T18: =I18*COS(R18)*$B$1 -> 25291.076 | U18: =B18-S18 -> 352392.79 | V18: =V17+T18 -> 75873.227 | W18: =A18+Q18*$B$1 -> 9249 | X18: =X17+$B$1 -> 360 | Y18: =Y17-B18+U18 -> 32792.791
A19: =W18 -> 9249 | B19: =U18 -> 352392.79 | C19: =IF(A19<=11000,A19*Constants!$B$2+Constants!$B$1,216.7) -> 228.0815 | D19: =IF(A19<=11000, Constants!$B$4*(1-0.0065*A19/Constants!$B$1)^5.2561, 22632*EXP(9.81*(11000-A19)/Constants!$B$6/C19)) -> 29626.222 | E19: =D19/(Constants!$B$6*Cruise!C19) -> 0.45258933 | F19: =SQRT(Constants!$B$8*Constants!$B$6*Cruise!C19) -> 302.72619 | G19: 290 | H19: =SQRT(5*((Constants!$B$3/Cruise!E19*((1+0.2*(Cruise!G19/661.5)^2)^3.5-1)+1)^0.286-1)) -> 0.69620327 | I19: =H19*F19 -> 210.75897 | J19: =I19/Constants!$B$9 -> 409.68301 | K19: =2*B19*Constants!$B$7/(Cruise!E19*Cruise!$B$2*Cruise!I19^2) -> 0.40083192 | L19: 0.02 | M19: =K19^2/(PI()*$B$3*$B$4)+L19 -> 0.026764769 | N19: =0.5*E19*Cruise!I19^2*Cruise!$B$2*Cruise!M19 -> 230832.64 | O19: =P19/$B$13 -> 57708.159 | P19: =N19 -> 230832.64 | Q19: =(P19-N19)*I19/B19/Constants!$B$7 -> 0 | R19: =ASIN(Q19/I19) -> 0 | S19: =P19*$B$1*$B$12/Constants!$B$7 -> 451.78253 | T19: =I19*COS(R19)*$B$1 -> 25291.076 | U19: =B19-S19 -> 351941.01 | V19: =V18+T19 -> 101164.3 | W19: =A19+Q19*$B$1 -> 9249 | X19: =X18+$B$1 -> 480 | Y19: =Y18-B19+U19 -> 32341.009
A20: =W19 -> 9249 | B20: =U19 -> 351941.01 | C20: =IF(A20<=11000,A20*Constants!$B$2+Constants!$B$1,216.7) -> 228.0815 | D20: =IF(A20<=11000, Constants!$B$4*(1-0.0065*A20/Constants!$B$1)^5.2561, 22632*EXP(9.81*(11000-A20)/Constants!$B$6/C20)) -> 29626.222 | E20: =D20/(Constants!$B$6*Cruise!C20) -> 0.45258933 | F20: =SQRT(Constants!$B$8*Constants!$B$6*Cruise!C20) -> 302.72619 | G20: 290 | H20: =SQRT(5*((Constants!$B$3/Cruise!E20*((1+0.2*(Cruise!G20/661.5)^2)^3.5-1)+1)^0.286-1)) -> 0.69620327 | I20: =H20*F20 -> 210.75897 | J20: =I20/Constants!$B$9 -> 409.68301 | K20: =2*B20*Constants!$B$7/(Cruise!E20*Cruise!$B$2*Cruise!I20^2) -> 0.40031804 | L20: 0.02 | M20: =K20^2/(PI()*$B$3*$B$4)+L20 -> 0.026747434 | N20: =0.5*E20*Cruise!I20^2*Cruise!$B$2*Cruise!M20 -> 230683.14 | O20: =P20/$B$13 -> 57670.784 | P20: =N20 -> 230683.14 | Q20: =(P20-N20)*I20/B20/Constants!$B$7 -> 0 | R20: =ASIN(Q20/I20) -> 0 | S20: =P20*$B$1*$B$12/Constants!$B$7 -> 451.48993 | T20: =I20*COS(R20)*$B$1 -> 25291.076 | U20: =B20-S20 -> 351489.52 | V20: =V19+T20 -> 126455.38 | W20: =A20+Q20*$B$1 -> 9249 | X20: =X19+$B$1 -> 600 | Y20: =Y19-B20+U20 -> 31889.519
A21: =W20 -> 9249 | B21: =U20 -> 351489.52 | C21: =IF(A21<=11000,A21*Constants!$B$2+Constants!$B$1,216.7) -> 228.0815 | D21: =IF(A21<=11000, Constants!$B$4*(1-0.0065*A21/Constants!$B$1)^5.2561, 22632*EXP(9.81*(11000-A21)/Constants!$B$6/C21)) -> 29626.222 | E21: =D21/(Constants!$B$6*Cruise!C21) -> 0.45258933 | F21: =SQRT(Constants!$B$8*Constants!$B$6*Cruise!C21) -> 302.72619 | G21: 290 | H21: =SQRT(5*((Constants!$B$3/Cruise!E21*((1+0.2*(Cruise!G21/661.5)^2)^3.5-1)+1)^0.286-1)) -> 0.69620327 | I21: =H21*F21 -> 210.75897 | J21: =I21/Constants!$B$9 -> 409.68301 | K21: =2*B21*Constants!$B$7/(Cruise!E21*Cruise!$B$2*Cruise!I21^2) -> 0.39980449 | L21: 0.02 | M21: =K21^2/(PI()*$B$3*$B$4)+L21 -> 0.026730133 | N21: =0.5*E21*Cruise!I21^2*Cruise!$B$2*Cruise!M21 -> 230533.92 | O21: =P21/$B$13 -> 57633.481 | P21: =N21 -> 230533.92 | Q21: =(P21-N21)*I21/B21/Constants!$B$7 -> 0 | R21: =ASIN(Q21/I21) -> 0 | S21: =P21*$B$1*$B$12/Constants!$B$7 -> 451.1979 | T21: =I21*COS(R21)*$B$1 -> 25291.076 | U21: =B21-S21 -> 351038.32 | V21: =V20+T21 -> 151746.45 | W21: =A21+Q21*$B$1 -> 9249 | X21: =X20+$B$1 -> 720 | Y21: =Y20-B21+U21 -> 31438.321
A22: =W21 -> 9249 | B22: =U21 -> 351038.32 | C22: =IF(A22<=11000,A22*Constants!$B$2+Constants!$B$1,216.7) -> 228.0815 | D22: =IF(A22<=11000, Constants!$B$4*(1-0.0065*A22/Constants!$B$1)^5.2561, 22632*EXP(9.81*(11000-A22)/Constants!$B$6/C22)) -> 29626.222 | E22: =D22/(Constants!$B$6*Cruise!C22) -> 0.45258933 | F22: =SQRT(Constants!$B$8*Constants!$B$6*Cruise!C22) -> 302.72619 | G22: 290 | H22: =SQRT(5*((Constants!$B$3/Cruise!E22*((1+0.2*(Cruise!G22/661.5)^2)^3.5-1)+1)^0.286-1)) -> 0.69620327 | I22: =H22*F22 -> 210.75897 | J22: =I22/Constants!$B$9 -> 409.68301 | K22: =2*B22*Constants!$B$7/(Cruise!E22*Cruise!$B$2*Cruise!I22^2) -> 0.39929127 | L22: 0.02 | M22: =K22^2/(PI()*$B$3*$B$4)+L22 -> 0.026712866 | N22: =0.5*E22*Cruise!I22^2*Cruise!$B$2*Cruise!M22 -> 230385 | O22: =P22/$B$13 -> 57596.25 | P22: =N22 -> 230385 | Q22: =(P22-N22)*I22/B22/Constants!$B$7 -> 0 | R22: =ASIN(Q22/I22) -> 0 | S22: =P22*$B$1*$B$12/Constants!$B$7 -> 450.90642 | T22: =I22*COS(R22)*$B$1 -> 25291.076 | U22: =B22-S22 -> 350587.41 | V22: =V21+T22 -> 177037.53 | W22: =A22+Q22*$B$1 -> 9249 | X22: =X21+$B$1 -> 840 | Y22: =Y21-B22+U22 -> 30987.414
A23: =W22 -> 9249 | B23: =U22 -> 350587.41 | C23: =IF(A23<=11000,A23*Constants!$B$2+Constants!$B$1,216.7) -> 228.0815 | D23: =IF(A23<=11000, Constants!$B$4*(1-0.0065*A23/Constants!$B$1)^5.2561, 22632*EXP(9.81*(11000-A23)/Constants!$B$6/C23)) -> 29626.222 | E23: =D23/(Constants!$B$6*Cruise!C23) -> 0.45258933 | F23: =SQRT(Constants!$B$8*Constants!$B$6*Cruise!C23) -> 302.72619 | G23: 290 | H23: =SQRT(5*((Constants!$B$3/Cruise!E23*((1+0.2*(Cruise!G23/661.5)^2)^3.5-1)+1)^0.286-1)) -> 0.69620327 | I23: =H23*F23 -> 210.75897 | J23: =I23/Constants!$B$9 -> 409.68301 | K23: =2*B23*Constants!$B$7/(Cruise!E23*Cruise!$B$2*Cruise!I23^2) -> 0.39877838 | L23: 0.02 | M23: =K23^2/(PI()*$B$3*$B$4)+L23 -> 0.026695632 | N23: =0.5*E23*Cruise!I23^2*Cruise!$B$2*Cruise!M23 -> 230236.36 | O23: =P23/$B$13 -> 57559.091 | P23: =N23 -> 230236.36 | Q23: =(P23-N23)*I23/B23/Constants!$B$7 -> 0 | R23: =ASIN(Q23/I23) -> 0 | S23: =P23*$B$1*$B$12/Constants!$B$7 -> 450.61552 | T23: =I23*COS(R23)*$B$1 -> 25291.076 | U23: =B23-S23 -> 350136.8 | V23: =V22+T23 -> 202328.61 | W23: =A23+Q23*$B$1 -> 9249 | X23: =X22+$B$1 -> 960 | Y23: =Y22-B23+U23 -> 30536.799
A24: =W23 -> 9249 | B24: =U23 -> 350136.8 | C24: =IF(A24<=11000,A24*Constants!$B$2+Constants!$B$1,216.7) -> 228.0815 | D24: =IF(A24<=11000, Constants!$B$4*(1-0.0065*A24/Constants!$B$1)^5.2561, 22632*EXP(9.81*(11000-A24)/Constants!$B$6/C24)) -> 29626.222 | E24: =D24/(Constants!$B$6*Cruise!C24) -> 0.45258933 | F24: =SQRT(Constants!$B$8*Constants!$B$6*Cruise!C24) -> 302.72619 | G24: 290 | H24: =SQRT(5*((Constants!$B$3/Cruise!E24*((1+0.2*(Cruise!G24/661.5)^2)^3.5-1)+1)^0.286-1)) -> 0.69620327 | I24: =H24*F24 -> 210.75897 | J24: =I24/Constants!$B$9 -> 409.68301 | K24: =2*B24*Constants!$B$7/(Cruise!E24*Cruise!$B$2*Cruise!I24^2) -> 0.39826583 | L24: 0.02 | M24: =K24^2/(PI()*$B$3*$B$4)+L24 -> 0.026678431 | N24: =0.5*E24*Cruise!I24^2*Cruise!$B$2*Cruise!M24 -> 230088.02 | O24: =P24/$B$13 -> 57522.004 | P24: =N24 -> 230088.02 | Q24: =(P24-N24)*I24/B24/Constants!$B$7 -> 0 | R24: =ASIN(Q24/I24) -> 0 | S24: =P24*$B$1*$B$12/Constants!$B$7 -> 450.32517 | T24: =I24*COS(R24)*$B$1 -> 25291.076 | U24: =B24-S24 -> 349686.47 | V24: =V23+T24 -> 227619.68 | W24: =A24+Q24*$B$1 -> 9249 | X24: =X23+$B$1 -> 1080 | Y24: =Y23-B24+U24 -> 30086.474
A25: =W24 -> 9249 | B25: =U24 -> 349686.47 | C25: =IF(A25<=11000,A25*Constants!$B$2+Constants!$B$1,216.7) -> 228.0815 | D25: =IF(A25<=11000, Constants!$B$4*(1-0.0065*A25/Constants!$B$1)^5.2561, 22632*EXP(9.81*(11000-A25)/Constants!$B$6/C25)) -> 29626.222 | E25: =D25/(Constants!$B$6*Cruise!C25) -> 0.45258933 | F25: =SQRT(Constants!$B$8*Constants!$B$6*Cruise!C25) -> 302.72619 | G25: 290 | H25: =SQRT(5*((Constants!$B$3/Cruise!E25*((1+0.2*(Cruise!G25/661.5)^2)^3.5-1)+1)^0.286-1)) -> 0.69620327 | I25: =H25*F25 -> 210.75897 | J25: =I25/Constants!$B$9 -> 409.68301 | K25: =2*B25*Constants!$B$7/(Cruise!E25*Cruise!$B$2*Cruise!I25^2) -> 0.3977536 | L25: 0.02 | M25: =K25^2/(PI()*$B$3*$B$4)+L25 -> 0.026661263 | N25: =0.5*E25*Cruise!I25^2*Cruise!$B$2*Cruise!M25 -> 229939.95 | O25: =P25/$B$13 -> 57484.988 | P25: =N25 -> 229939.95 | Q25: =(P25-N25)*I25/B25/Constants!$B$7 -> 0 | R25: =ASIN(Q25/I25) -> 0 | S25: =P25*$B$1*$B$12/Constants!$B$7 -> 450.03538 | T25: =I25*COS(R25)*$B$1 -> 25291.076 | U25: =B25-S25 -> 349236.44 | V25: =V24+T25 -> 252910.76 | W25: =A25+Q25*$B$1 -> 9249 | X25: =X24+$B$1 -> 1200 | Y25: =Y24-B25+U25 -> 29636.438
A26: =W25 -> 9249 | B26: =U25 -> 349236.44 | C26: =IF(A26<=11000,A26*Constants!$B$2+Constants!$B$1,216.7) -> 228.0815 | D26: =IF(A26<=11000, Constants!$B$4*(1-0.0065*A26/Constants!$B$1)^5.2561, 22632*EXP(9.81*(11000-A26)/Constants!$B$6/C26)) -> 29626.222 | E26: =D26/(Constants!$B$6*Cruise!C26) -> 0.45258933 | F26: =SQRT(Constants!$B$8*Constants!$B$6*Cruise!C26) -> 302.72619 | G26: 290 | H26: =SQRT(5*((Constants!$B$3/Cruise!E26*((1+0.2*(Cruise!G26/661.5)^2)^3.5-1)+1)^0.286-1)) -> 0.69620327 | I26: =H26*F26 -> 210.75897 | J26: =I26/Constants!$B$9 -> 409.68301 | K26: =2*B26*Constants!$B$7/(Cruise!E26*Cruise!$B$2*Cruise!I26^2) -> 0.39724171 | L26: 0.02 | M26: =K26^2/(PI()*$B$3*$B$4)+L26 -> 0.026644128 | N26: =0.5*E26*Cruise!I26^2*Cruise!$B$2*Cruise!M26 -> 229792.17 | O26: =P26/$B$13 -> 57448.044 | P26: =N26 -> 229792.17 | Q26: =(P26-N26)*I26/B26/Constants!$B$7 -> 0 | R26: =ASIN(Q26/I26) -> 0 | S26: =P26*$B$1*$B$12/Constants!$B$7 -> 449.74615 | T26: =I26*COS(R26)*$B$1 -> 25291.076 | U26: =B26-S26 -> 348786.69 | V26: =V25+T26 -> 278201.83 | W26: =A26+Q26*$B$1 -> 9249 | X26: =X25+$B$1 -> 1320 | Y26: =Y25-B26+U26 -> 29186.692
A27: =W26 -> 9249 | B27: =U26 -> 348786.69 | C27: =IF(A27<=11000,A27*Constants!$B$2+Constants!$B$1,216.7) -> 228.0815 | D27: =IF(A27<=11000, Constants!$B$4*(1-0.0065*A27/Constants!$B$1)^5.2561, 22632*EXP(9.81*(11000-A27)/Constants!$B$6/C27)) -> 29626.222 | E27: =D27/(Constants!$B$6*Cruise!C27) -> 0.45258933 | F27: =SQRT(Constants!$B$8*Constants!$B$6*Cruise!C27) -> 302.72619 | G27: 290 | H27: =SQRT(5*((Constants!$B$3/Cruise!E27*((1+0.2*(Cruise!G27/661.5)^2)^3.5-1)+1)^0.286-1)) -> 0.69620327 | I27: =H27*F27 -> 210.75897 | J27: =I27/Constants!$B$9 -> 409.68301 | K27: =2*B27*Constants!$B$7/(Cruise!E27*Cruise!$B$2*Cruise!I27^2) -> 0.39673014 | L27: 0.02 | M27: =K27^2/(PI()*$B$3*$B$4)+L27 -> 0.026627027 | N27: =0.5*E27*Cruise!I27^2*Cruise!$B$2*Cruise!M27 -> 229644.68 | O27: =P27/$B$13 -> 57411.171 | P27: =N27 -> 229644.68 | Q27: =(P27-N27)*I27/B27/Constants!$B$7 -> 0 | R27: =ASIN(Q27/I27) -> 0 | S27: =P27*$B$1*$B$12/Constants!$B$7 -> 449.45748 | T27: =I27*COS(R27)*$B$1 -> 25291.076 | U27: =B27-S27 -> 348337.23 | V27: =V26+T27 -> 303492.91 | W27: =A27+Q27*$B$1 -> 9249 | X27: =X26+$B$1 -> 1440 | Y27: =Y26-B27+U27 -> 28737.235
A28: =W27 -> 9249 | B28: =U27 -> 348337.23 | C28: =IF(A28<=11000,A28*Constants!$B$2+Constants!$B$1,216.7) -> 228.0815 | D28: =IF(A28<=11000, Constants!$B$4*(1-0.0065*A28/Constants!$B$1)^5.2561, 22632*EXP(9.81*(11000-A28)/Constants!$B$6/C28)) -> 29626.222 | E28: =D28/(Constants!$B$6*Cruise!C28) -> 0.45258933 | F28: =SQRT(Constants!$B$8*Constants!$B$6*Cruise!C28) -> 302.72619 | G28: 290 | H28: =SQRT(5*((Constants!$B$3/Cruise!E28*((1+0.2*(Cruise!G28/661.5)^2)^3.5-1)+1)^0.286-1)) -> 0.69620327 | I28: =H28*F28 -> 210.75897 | J28: =I28/Constants!$B$9 -> 409.68301 | K28: =2*B28*Constants!$B$7/(Cruise!E28*Cruise!$B$2*Cruise!I28^2) -> 0.3962189 | L28: 0.02 | M28: =K28^2/(PI()*$B$3*$B$4)+L28 -> 0.026609958 | N28: =0.5*E28*Cruise!I28^2*Cruise!$B$2*Cruise!M28 -> 229497.47 | O28: =P28/$B$13 -> 57374.369 | P28: =N28 -> 229497.47 | Q28: =(P28-N28)*I28/B28/Constants!$B$7 -> 0 | R28: =ASIN(Q28/I28) -> 0 | S28: =P28*$B$1*$B$12/Constants!$B$7 -> 449.16937 | T28: =I28*COS(R28)*$B$1 -> 25291.076 | U28: =B28-S28 -> 347888.07 | V28: =V27+T28 -> 328783.99 | W28: =A28+Q28*$B$1 -> 9249 | X28: =X27+$B$1 -> 1560 | Y28: =Y27-B28+U28 -> 28288.065
... A45: =W44 -> 9249 | B45: =U44 -> 340740.09 | C45: =IF(A45<=11000,A45*Constants!$B$2+Constants!$B$1,216.7) -> 228.0815 | D45: =IF(A45<=11000, Constants!$B$4*(1-0.0065*A45/Constants!$B$1)^5.2561, 22632*EXP(9.81*(11000-A45)/Constants!$B$6/C45)) -> 29626.222 | E45: =D45/(Constants!$B$6*Cruise!C45) -> 0.45258933 | F45: =SQRT(Constants!$B$8*Constants!$B$6*Cruise!C45) -> 302.72619 | G45: 290 | H45: =SQRT(5*((Constants!$B$3/Cruise!E45*((1+0.2*(Cruise!G45/661.5)^2)^3.5-1)+1)^0.286-1)) -> 0.69620327 | I45: =H45*F45 -> 210.75897 | J45: =I45/Constants!$B$9 -> 409.68301 | K45: =2*B45*Constants!$B$7/(Cruise!E45*Cruise!$B$2*Cruise!I45^2) -> 0.38757747 | L45: 0.02 | M45: =K45^2/(PI()*$B$3*$B$4)+L45 -> 0.026324779 | N45: =0.5*E45*Cruise!I45^2*Cruise!$B$2*Cruise!M45 -> 227037.95 | O45: =P45/$B$13 -> 56759.488 | P45: =N45 -> 227037.95 | Q45: =(P45-N45)*I45/B45/Constants!$B$7 -> 0 | R45: =ASIN(Q45/I45) -> 0 | S45: =P45*$B$1*$B$12/Constants!$B$7 -> 444.35562 | T45: =I45*COS(R45)*$B$1 -> 25291.076 | U45: =B45-S45 -> 340295.73 | V45: =V44+T45 -> 758732.27 | W45: =A45+Q45*$B$1 -> 9249 | X45: =X44+$B$1 -> 3600 | Y45: =Y44-B45+U45 -> 20695.733

Sheet Descend
A1: Time step | B1: 60 | C1: s
A2: Wing area | B2: 858 | C2: m^2
A3: Aspect ratio | B3: 9
A4: e | B4: 0.84
A5: Empty weight | B5: 276800 | C5: kg
A6: Payload | B6: 42800 | C6: Kg
A7: Fuel | B7: 35186 | C7: l | D7: Fuel | E7: =B7*0.804 -> 28289.544 | F7: kg | H7: Fuel | I7: 28290 | J7: kg | K7: => | L7: Fuel | M7: =I7/0.804 -> 35186.567 | N7: l
A8: Thrust | B8: 0 | C8: 0.9 | D8: Velocity (M)
B9: 338000 | C9: 180000 | D9: Thrust (N)
A10: Lambda | B10: =(B9-C9)/C8 -> 175555.56
A11: Thrust laps rate | B11: 0.96
A12: TSFC | B12: 0.00016 | C12: N/N/S
A13: Num Engines | B13: 4
A15: Altitude | B15: Mass | C15: Temperature | D15: Preassure | E15: Air density | F15: Speed of sound | G15: IAS | H15: Mtrue | I15: TAS (m/s) | J15: TAS (Knot) | K15: Lift coef. | L15: Cdrag_0 | M15: Drag coef. | N15: Drag | O15: Thrust | P15: Total Thrust | Q15: dh/dt | R15: Climbing angle | S15: dW/dt | T15: Distance | U15: New mass | V15: Cumulative distance | W15: Cumulative altitude | X15: Flight time | Y15: Remaining Fuel
A16: 9150.1957 | B16: =B5+B6+E7 -> 347889.54 | C16: =IF(A16<=11000,A16*Constants!$B$2+Constants!$B$1,216.7) -> 228.72373 | D16: =IF(A16<=11000, Constants!$B$4*(1-0.0065*A16/Constants!$B$1)^5.2561, 22632*EXP(9.81*(11000-A16)/Constants!$B$6/C16)) -> 30067.326 | E16: =D16/(Constants!$B$6*Descend!C16) -> 0.45803819 | F16: =SQRT(Constants!$B$8*Constants!$B$6*Descend!C16) -> 303.1521 | G16: 290 | H16: =SQRT(5*((Constants!$B$3/Descend!E16*((1+0.2*(Descend!G16/661.5)^2)^3.5-1)+1)^0.286-1)) -> 0.69248483 | I16: =H16*F16 -> 209.92823 | J16: =I16/Constants!$B$9 -> 408.06818 | K16: =2*B16*Constants!$B$7/(Descend!E16*Descend!$B$2*Descend!I16^2) -> 0.39410298 | L16: 0.02 | M16: =K16^2/(PI()*$B$3*$B$4)+L16 -> 0.026539548 | N16: =0.5*E16*Descend!I16^2*Descend!$B$2*Descend!M16 -> 229823.37 | O16: =0.1*($B$9-$B$10*H16)*(E16/Constants!$B$3)^$B$11 -> 8417.31 | P16: =IF(O16>0, O16*$B$13, 0) -> 33669.24 | Q16: =(P16-N16)*I16/B16/Constants!$B$7 -> -12.06585 | R16: =ASIN(Q16/I16) -> -0.057507765 | S16: =P16*$B$1*$B$12/Constants!$B$7 -> 32.948492 | T16: =I16*COS(R16)*$B$1 -> 12574.872 | U16: =B16-S16 -> 347856.6 | V16: =T16 -> 12574.872 | W16: =A16+Q16*$B$1 -> 8426.2447 | X16: =$B$1 -> 60 | Y16: =$E$7-B16+U16 -> 28256.596
A17: =W16 -> 8426.2447 | B17: =U16 -> 347856.6 | C17: =IF(A17<=11000,A17*Constants!$B$2+Constants!$B$1,216.7) -> 233.42941 | D17: =IF(A17<=11000, Constants!$B$4*(1-0.0065*A17/Constants!$B$1)^5.2561, 22632*EXP(9.81*(11000-A17)/Constants!$B$6/C17)) -> 33464.289 | E17: =D17/(Constants!$B$6*Descend!C17) -> 0.49950994 | F17: =SQRT(Constants!$B$8*Constants!$B$6*Descend!C17) -> 306.25469 | G17: 290 | H17: =SQRT(5*((Constants!$B$3/Descend!E17*((1+0.2*(Descend!G17/661.5)^2)^3.5-1)+1)^0.286-1)) -> 0.66602547 | I17: =H17*F17 -> 203.97342 | J17: =I17/Constants!$B$9 -> 396.49296 | K17: =2*B17*Constants!$B$7/(Descend!E17*Descend!$B$2*Descend!I17^2) -> 0.38275481 | L17: 0.02 | M17: =K17^2/(PI()*$B$3*$B$4)+L17 -> 0.026168359 | N17: =0.5*E17*Descend!I17^2*Descend!$B$2*Descend!M17 -> 233305.56 | O17: =0.1*($B$9-$B$10*H17)*(E17/Constants!$B$3)^$B$11 -> 9343.9907 | P17: =IF(O17>0, O17*$B$13, 0) -> 37375.963 | Q17: =(P17-N17)*I17/B17/Constants!$B$7 -> -11.71128 | R17: =ASIN(Q17/I17) -> -0.05744731 | S17: =P17*$B$1*$B$12/Constants!$B$7 -> 36.575866 | T17: =I17*COS(R17)*$B$1 -> 12218.216 | U17: =B17-S17 -> 347820.02 | V17: =V16+T17 -> 24793.088 | W17: =A17+Q17*$B$1 -> 7723.5679 | X17: =X16+$B$1 -> 120 | Y17: =Y16-B17+U17 -> 28220.02
A18: =W17 -> 7723.5679 | B18: =U17 -> 347820.02 | C18: =IF(A18<=11000,A18*Constants!$B$2+Constants!$B$1,216.7) -> 237.99681 | D18: =IF(A18<=11000, Constants!$B$4*(1-0.0065*A18/Constants!$B$1)^5.2561, 22632*EXP(9.81*(11000-A18)/Constants!$B$6/C18)) -> 37052.255 | E18: =D18/(Constants!$B$6*Descend!C18) -> 0.54245237 | F18: =SQRT(Constants!$B$8*Constants!$B$6*Descend!C18) -> 309.23635 | G18: 290 | H18: =SQRT(5*((Constants!$B$3/Descend!E18*((1+0.2*(Descend!G18/661.5)^2)^3.5-1)+1)^0.286-1)) -> 0.64161441 | I18: =H18*F18 -> 198.4105 | J18: =I18/Constants!$B$9 -> 385.67948 | K18: =2*B18*Constants!$B$7/(Descend!E18*Descend!$B$2*Descend!I18^2) -> 0.37245636 | L18: 0.02 | M18: =K18^2/(PI()*$B$3*$B$4)+L18 -> 0.025840891 | N18: =0.5*E18*Descend!I18^2*Descend!$B$2*Descend!M18 -> 236731.3 | O18: =0.1*($B$9-$B$10*H18)*(E18/Constants!$B$3)^$B$11 -> 10309.92 | P18: =IF(O18>0, O18*$B$13, 0) -> 41239.681 | Q18: =(P18-N18)*I18/B18/Constants!$B$7 -> -11.367611 | R18: =ASIN(Q18/I18) -> -0.057324785 | S18: =P18*$B$1*$B$12/Constants!$B$7 -> 40.356875 | T18: =I18*COS(R18)*$B$1 -> 11885.075 | U18: =B18-S18 -> 347779.66 | V18: =V17+T18 -> 36678.163 | W18: =A18+Q18*$B$1 -> 7041.5112 | X18: =X17+$B$1 -> 180 | Y18: =Y17-B18+U18 -> 28179.663
A19: =W18 -> 7041.5112 | B19: =U18 -> 347779.66 | C19: =IF(A19<=11000,A19*Constants!$B$2+Constants!$B$1,216.7) -> 242.43018 | D19: =IF(A19<=11000, Constants!$B$4*(1-0.0065*A19/Constants!$B$1)^5.2561, 22632*EXP(9.81*(11000-A19)/Constants!$B$6/C19)) -> 40826.781 | E19: =D19/(Constants!$B$6*Descend!C19) -> 0.58678171 | F19: =SQRT(Constants!$B$8*Constants!$B$6*Descend!C19) -> 312.10326 | G19: 290 | H19: =SQRT(5*((Constants!$B$3/Descend!E19*((1+0.2*(Descend!G19/661.5)^2)^3.5-1)+1)^0.286-1)) -> 0.61905159 | I19: =H19*F19 -> 193.20802 | J19: =I19/Constants!$B$9 -> 375.56667 | K19: =2*B19*Constants!$B$7/(Descend!E19*Descend!$B$2*Descend!I19^2) -> 0.36306888 | L19: 0.02 | M19: =K19^2/(PI()*$B$3*$B$4)+L19 -> 0.025550171 | N19: =0.5*E19*Descend!I19^2*Descend!$B$2*Descend!M19 -> 240092.16 | O19: =0.1*($B$9-$B$10*H19)*(E19/Constants!$B$3)^$B$11 -> 11312.867 | P19: =IF(O19>0, O19*$B$13, 0) -> 45251.468 | Q19: =(P19-N19)*I19/B19/Constants!$B$7 -> -11.033965 | R19: =ASIN(Q19/I19) -> -0.057140341 | S19: =P19*$B$1*$B$12/Constants!$B$7 -> 44.282782 | T19: =I19*COS(R19)*$B$1 -> 11573.561 | U19: =B19-S19 -> 347735.38 | V19: =V18+T19 -> 48251.725 | W19: =A19+Q19*$B$1 -> 6379.4733 | X19: =X18+$B$1 -> 240 | Y19: =Y18-B19+U19 -> 28135.38
A20: =W19 -> 6379.4733 | B20: =U19 -> 347735.38 | C20: =IF(A20<=11000,A20*Constants!$B$2+Constants!$B$1,216.7) -> 246.73342 | D20: =IF(A20<=11000, Constants!$B$4*(1-0.0065*A20/Constants!$B$1)^5.2561, 22632*EXP(9.81*(11000-A20)/Constants!$B$6/C20)) -> 44782.529 | E20: =D20/(Constants!$B$6*Descend!C20) -> 0.63241001 | F20: =SQRT(Constants!$B$8*Constants!$B$6*Descend!C20) -> 314.86106 | G20: 290 | H20: =SQRT(5*((Constants!$B$3/Descend!E20*((1+0.2*(Descend!G20/661.5)^2)^3.5-1)+1)^0.286-1)) -> 0.59816066 | I20: =H20*F20 -> 188.3375 | J20: =I20/Constants!$B$9 -> 366.09913 | K20: =2*B20*Constants!$B$7/(Descend!E20*Descend!$B$2*Descend!I20^2) -> 0.35447715 | L20: 0.02 | M20: =K20^2/(PI()*$B$3*$B$4)+L20 -> 0.025290599 | N20: =0.5*E20*Descend!I20^2*Descend!$B$2*Descend!M20 -> 243382.16 | O20: =0.1*($B$9-$B$10*H20)*(E20/Constants!$B$3)^$B$11 -> 12350.502 | P20: =IF(O20>0, O20*$B$13, 0) -> 49402.009 | Q20: =(P20-N20)*I20/B20/Constants!$B$7 -> -10.709673 | R20: =ASIN(Q20/I20) -> -0.056894953 | S20: =P20*$B$1*$B$12/Constants!$B$7 -> 48.344474 | T20: =I20*COS(R20)*$B$1 -> 11281.965 | U20: =B20-S20 -> 347687.04 | V20: =V19+T20 -> 59533.69 | W20: =A20+Q20*$B$1 -> 5736.8929 | X20: =X19+$B$1 -> 300 | Y20: =Y19-B20+U20 -> 28087.036
A21: =W20 -> 5736.8929 | B21: =U20 -> 347687.04 | C21: =IF(A21<=11000,A21*Constants!$B$2+Constants!$B$1,216.7) -> 250.9102 | D21: =IF(A21<=11000, Constants!$B$4*(1-0.0065*A21/Constants!$B$1)^5.2561, 22632*EXP(9.81*(11000-A21)/Constants!$B$6/C21)) -> 48913.337 | E21: =D21/(Constants!$B$6*Descend!C21) -> 0.67924599 | F21: =SQRT(Constants!$B$8*Constants!$B$6*Descend!C21) -> 317.51491 | G21: =VLOOKUP(TRUNC(A21/1000),Flight!$A$3:$D$17,4,FALSE) -> 290 | H21: =SQRT(5*((Constants!$B$3/Descend!E21*((1+0.2*(Descend!G21/661.5)^2)^3.5-1)+1)^0.286-1)) -> 0.57878564 | I21: =H21*F21 -> 183.77307 | J21: =I21/Constants!$B$9 -> 357.22658 | K21: =2*B21*Constants!$B$7/(Descend!E21*Descend!$B$2*Descend!I21^2) -> 0.3465847 | L21: 0.02 | M21: =K21^2/(PI()*$B$3*$B$4)+L21 -> 0.025057631 | N21: =0.5*E21*Descend!I21^2*Descend!$B$2*Descend!M21 -> 246597.19 | O21: =0.1*($B$9-$B$10*H21)*(E21/Constants!$B$3)^$B$11 -> 13420.424 | P21: =IF(O21>0, O21*$B$13, 0) -> 53681.695 | Q21: =(P21-N21)*I21/B21/Constants!$B$7 -> -10.394209 | R21: =ASIN(Q21/I21) -> -0.056590225 | S21: =P21*$B$1*$B$12/Constants!$B$7 -> 52.532546 | T21: =I21*COS(R21)*$B$1 -> 11008.733 | U21: =B21-S21 -> 347634.5 | V21: =V20+T21 -> 70542.423 | W21: =A21+Q21*$B$1 -> 5113.2403 | X21: =X20+$B$1 -> 360 | Y21: =Y20-B21+U21 -> 28034.503
A22: =W21 -> 5113.2403 | B22: =U21 -> 347634.5 | C22: =IF(A22<=11000,A22*Constants!$B$2+Constants!$B$1,216.7) -> 254.96394 | D22: =IF(A22<=11000, Constants!$B$4*(1-0.0065*A22/Constants!$B$1)^5.2561, 22632*EXP(9.81*(11000-A22)/Constants!$B$6/C22)) -> 53212.309 | E22: =D22/(Constants!$B$6*Descend!C22) -> 0.72719594 | F22: =SQRT(Constants!$B$8*Constants!$B$6*Descend!C22) -> 320.06954 | G22: =VLOOKUP(TRUNC(A22/1000),Flight!$A$3:$D$17,4,FALSE) -> 290 | H22: =SQRT(5*((Constants!$B$3/Descend!E22*((1+0.2*(Descend!G22/661.5)^2)^3.5-1)+1)^0.286-1)) -> 0.5607881 | I22: =H22*F22 -> 179.49119 | J22: =I22/Constants!$B$9 -> 348.90326 | K22: =2*B22*Constants!$B$7/(Descend!E22*Descend!$B$2*Descend!I22^2) -> 0.33931017 | L22: 0.02 | M22: =K22^2/(PI()*$B$3*$B$4)+L22 -> 0.024847548 | N22: =0.5*E22*Descend!I22^2*Descend!$B$2*Descend!M22 -> 249734.5 | O22: =0.1*($B$9-$B$10*H22)*(E22/Constants!$B$3)^$B$11 -> 14520.176 | P22: =IF(O22>0, O22*$B$13, 0) -> 58080.705 | Q22: =(P22-N22)*I22/B22/Constants!$B$7 -> -10.087154 | R22: =ASIN(Q22/I22) -> -0.056228229 | S22: =P22*$B$1*$B$12/Constants!$B$7 -> 56.837387 | T22: =I22*COS(R22)*$B$1 -> 10752.451 | U22: =B22-S22 -> 347577.67 | V22: =V21+T22 -> 81294.874 | W22: =A22+Q22*$B$1 -> 4508.0111 | X22: =X21+$B$1 -> 420 | Y22: =Y21-B22+U22 -> 27977.666
A23: =W22 -> 4508.0111 | B23: =U22 -> 347577.67 | C23: =IF(A23<=11000,A23*Constants!$B$2+Constants!$B$1,216.7) -> 258.89793 | D23: =IF(A23<=11000, Constants!$B$4*(1-0.0065*A23/Constants!$B$1)^5.2561, 22632*EXP(9.81*(11000-A23)/Constants!$B$6/C23)) -> 57671.893 | E23: =D23/(Constants!$B$6*Descend!C23) -> 0.77616442 | F23: =SQRT(Constants!$B$8*Constants!$B$6*Descend!C23) -> 322.52936 | G23: =VLOOKUP(TRUNC(A23/1000),Flight!$A$3:$D$17,4,FALSE) -> 270 | H23: =SQRT(5*((Constants!$B$3/Descend!E23*((1+0.2*(Descend!G23/661.5)^2)^3.5-1)+1)^0.286-1)) -> 0.50732558 | I23: =H23*F23 -> 163.62739 | J23: =I23/Constants!$B$9 -> 318.06648 | K23: =2*B23*Constants!$B$7/(Descend!E23*Descend!$B$2*Descend!I23^2) -> 0.38247039 | L23: 0.02 | M23: =K23^2/(PI()*$B$3*$B$4)+L23 -> 0.026159195 | N23: =0.5*E23*Descend!I23^2*Descend!$B$2*Descend!M23 -> 233210.14 | O23: =0.1*($B$9-$B$10*H23)*(E23/Constants!$B$3)^$B$11 -> 16063.233 | P23: =IF(O23>0, O23*$B$13, 0) -> 64252.931 | Q23: =(P23-N23)*I23/B23/Constants!$B$7 -> -8.1079652 | R23: =ASIN(Q23/I23) -> -0.049571692 | S23: =P23*$B$1*$B$12/Constants!$B$7 -> 62.877486 | T23: =I23*COS(R23)*$B$1 -> 9805.5834 | U23: =B23-S23 -> 347514.79 | V23: =V22+T23 -> 91100.458 | W23: =A23+Q23*$B$1 -> 4021.5332 | X23: =X22+$B$1 -> 480 | Y23: =Y22-B23+U23 -> 27914.788
